2016-11-02 04:23:27,368 - playground.twisted.endpoints.GateEndpoint.GateService - INFO - Connecting to gate 127.0.0.1 19091 with callback port 17730
2016-11-02 04:23:27,369 - playground.twisted.endpoints.GateEndpoint.GateService - INFO - Starting outbound connection to gate.
2016-11-02 04:23:27,398 - root - WARNING - [ERROR(Warning) __controlConnectFailed::99 -> ROOT/Default Logging Error Handler ]
[DETAILS]
Could not get control channel connection: [Failure instance: Traceback (failure with no frames): <class 'twisted.internet.error.ConnectionRefusedError'>: Connection was refused by other side: 111: Connection refused.
]
	Associated Trace:   File "echotest2.py", line 253, in <module>
    reactor.run()
  File "/usr/local/lib/python2.7/dist-packages/twisted/internet/base.py", line 1195, in run
    self.mainLoop()
  File "/usr/local/lib/python2.7/dist-packages/twisted/internet/base.py", line 1207, in mainLoop
    self.doIteration(t)
  File "/usr/local/lib/python2.7/dist-packages/twisted/internet/epollreactor.py", line 396, in doPoll
    log.callWithLogger(selectable, _drdw, selectable, fd, event)
  File "/usr/local/lib/python2.7/dist-packages/twisted/python/log.py", line 101, in callWithLogger
    return callWithContext({"system": lp}, func, *args, **kw)
  File "/usr/local/lib/python2.7/dist-packages/twisted/python/log.py", line 84, in callWithContext
    return context.call({ILogContext: newCtx}, func, *args, **kw)
  File "/usr/local/lib/python2.7/dist-packages/twisted/python/context.py", line 118, in callWithContext
    return self.currentContext().callWithContext(ctx, func, *args, **kw)
  File "/usr/local/lib/python2.7/dist-packages/twisted/python/context.py", line 81, in callWithContext
    return func(*args,**kw)
  File "/usr/local/lib/python2.7/dist-packages/twisted/internet/posixbase.py", line 597, in _doReadOrWrite
    why = selectable.doRead()
  File "/usr/local/lib/python2.7/dist-packages/twisted/internet/tcp.py", line 551, in doConnect
    self.failIfNotConnected(error.getConnectError((err, strerror(err))))
  File "/usr/local/lib/python2.7/dist-packages/twisted/internet/tcp.py", line 453, in failIfNotConnected
    self.connector.connectionFailed(failure.Failure(err))
  File "/usr/local/lib/python2.7/dist-packages/twisted/internet/base.py", line 1080, in connectionFailed
    self.factory.clientConnectionFailed(self, reason)
  File "/usr/local/lib/python2.7/dist-packages/twisted/internet/endpoints.py", line 245, in clientConnectionFailed
    self._onConnection.errback(reason)
  File "/usr/local/lib/python2.7/dist-packages/twisted/internet/defer.py", line 434, in errback
    self._startRunCallbacks(fail)
  File "/usr/local/lib/python2.7/dist-packages/twisted/internet/defer.py", line 501, in _startRunCallbacks
    self._runCallbacks()
  File "/usr/local/lib/python2.7/dist-packages/twisted/internet/defer.py", line 587, in _runCallbacks
    current.result = callback(current.result, *args, **kw)
  File "/home/fady/Documents/PlayGround/secondtest/src/playground/twisted/endpoints/GateEndpoint.py", line 99, in __controlConnectFailed
    errReporter.warning("Could not get control channel connection: %s" % failure)


2016-11-02 04:23:27,398 - __main__ - ERROR - [Failure instance: Traceback (failure with no frames): <class 'twisted.internet.error.ConnectionRefusedError'>: Connection was refused by other side: 111: Connection refused.
]
